import Dispatch

/// Provides `catch` and `recover` to your object that conforms to `CancellableThenable`
public protocol CancellableCatchMixin: CancellableThenable {
    /// Type of the delegate `catchable`
    associatedtype C: CatchMixin

    /// Delegate `catchable` for this CancellablePromise
    var catchable: C { get }
}

public extension CancellableCatchMixin {
    /**
     The provided closure executes when this cancellable promise rejects.
     
     Rejecting a promise cascades: rejecting all subsequent promises (unless
     recover is invoked) thus you will typically place your catch at the end
     of a chain. Often utility promises will not have a catch, instead
     delegating the error handling to the caller.
     
     - Parameter on: The dispatcher that executes the provided closure.
     - Parameter policy: The default policy does not execute your handler for cancellation errors.
     - Parameter execute: The handler to execute if this promise is rejected.
     - Returns: A promise finalizer.
     - SeeAlso: [Cancellation](https://github.com/mxcl/PromiseKit/blob/master/Documentation/CommonPatterns.md#cancellation)
     */
    @discardableResult
    func `catch`(on: Dispatcher = conf.dd, policy: CatchPolicy = conf.catchPolicy, _ body: @escaping(Error) -> Void) -> CancellableFinalizer {
        return CancellableFinalizer(self.catchable.catch(on: on, policy: policy, body), cancel: self.cancelContext)
    }

    /**
     The provided closure executes when this cancellable promise rejects with the specific error passed in.
     A final `catch` is still required at the end of the chain.

     Rejecting a promise cascades: rejecting all subsequent promises (unless
     recover is invoked) thus you will typically place your catch at the end
     of a chain. Often utility promises will not have a catch, instead
     delegating the error handling to the caller.

     - Parameter only: The specific error to be caught and handled.
     - Parameter on: The queue to which the provided closure dispatches.
     - Parameter execute: The handler to execute if this promise is rejected with the provided error.
     - Note: Since this method handles only specific errors, supplying a `CatchPolicy` is unsupported. You can instead specify e.g. your cancellable error.
     - SeeAlso: [Cancellation](https://github.com/mxcl/PromiseKit/blob/master/Documentation/CommonPatterns.md#cancellation)
     */
    func `catch`<E: Swift.Error>(only: E, on: Dispatcher = conf.dd, _ body: @escaping(E) -> Void) -> CancellableCascadingFinalizer where E: Equatable {
        return CancellableCascadingFinalizer(self.catchable.catch(only: only, on: on, body), cancel: self.cancelContext)
    }

    /**
     The provided closure executes when this cancellable promise rejects with an error of the type passed in.
     A final `catch` is still required at the end of the chain.

     Rejecting a promise cascades: rejecting all subsequent promises (unless
     recover is invoked) thus you will typically place your catch at the end
     of a chain. Often utility promises will not have a catch, instead
     delegating the error handling to the caller.

     - Parameter only: The error type to be caught and handled.
     - Parameter on: The queue to which the provided closure dispatches.
     - Parameter execute: The handler to execute if this promise is rejected with the provided error type.
     - SeeAlso: [Cancellation](https://github.com/mxcl/PromiseKit/blob/master/Documentation/CommonPatterns.md#cancellation)
     */
    func `catch`<E: Swift.Error>(only: E.Type, on: Dispatcher = conf.dd, policy: CatchPolicy = conf.catchPolicy, _ body: @escaping(E) -> Void) -> CancellableCascadingFinalizer {
        return CancellableCascadingFinalizer(self.catchable.catch(only: only, on: on, policy: policy, body), cancel: self.cancelContext)
    }
}

public class CancelContextFinalizer {
    /// The CancelContext associated with this finalizer
    public let cancelContext: CancelContext
    
    init(cancel: CancelContext) {
        self.cancelContext = cancel
    }
    
    /**
     Cancel all members of the promise chain and their associated asynchronous operations.

     - Parameter error: Specifies the cancellation error to use for the cancel operation, defaults to `PMKError.cancelled`
     */
    public func cancel(with error: Error = PMKError.cancelled) {
        cancelContext.cancel(with: error)
    }
    
    /**
     True if all members of the promise chain have been successfully cancelled, false otherwise.
     */
    public var isCancelled: Bool {
        return cancelContext.isCancelled
    }
    
    /**
     True if `cancel` has been called on the CancelContext associated with this promise, false otherwise.  `cancelAttempted` will be true if `cancel` is called on any promise in the chain.
     */
    public var cancelAttempted: Bool {
        return cancelContext.cancelAttempted
    }
    
    /**
     The cancellation error generated when the promise is cancelled, or `nil` if not cancelled.
     */
    public var cancelledError: Error? {
        return cancelContext.cancelledError
    }
}

/**
 Cancellable finalizer returned from `catch`.  Use `finally` to specify a code block that executes when the promise chain resolves.
 */
public class CancellableFinalizer: CancelContextFinalizer {
    let pmkFinalizer: PMKFinalizer

    init(_ pmkFinalizer: PMKFinalizer, cancel: CancelContext) {
        self.pmkFinalizer = pmkFinalizer
        super.init(cancel: cancel)
    }
    
    /// `finally` is the same as `ensure`, but it is not chainable
    @discardableResult
    public func finally(on: Dispatcher = conf.dd, _ body: @escaping () -> Void) -> CancelContext {
        pmkFinalizer.finally(on: on, body)
        return cancelContext
    }
}

public class CancellableCascadingFinalizer: CancelContextFinalizer {
    let pmkCascadingFinalizer: PMKCascadingFinalizer

    init(_ pmkCascadingFinalizer: PMKCascadingFinalizer, cancel: CancelContext) {
        self.pmkCascadingFinalizer = pmkCascadingFinalizer
        super.init(cancel: cancel)
    }
    
    /**
     The provided closure executes when this promise rejects.

     Rejecting a promise cascades: rejecting all subsequent promises (unless
     recover is invoked) thus you will typically place your catch at the end
     of a chain. Often utility promises will not have a catch, instead
     delegating the error handling to the caller.

     - Parameter on: The queue to which the provided closure dispatches.
     - Parameter policy: The default policy does not execute your handler for cancellation errors.
     - Parameter execute: The handler to execute if this promise is rejected.
     - Returns: A promise finalizer.
     - SeeAlso: [Cancellation](https://github.com/mxcl/PromiseKit/blob/master/Documentation/CommonPatterns.md#cancellation)
     */
    @discardableResult
    public func `catch`(on: Dispatcher = conf.dd, policy: CatchPolicy = conf.catchPolicy, _ body: @escaping(Error) -> Void) -> CancellableFinalizer {
        return CancellableFinalizer(pmkCascadingFinalizer.catch(on: on, policy: policy, body), cancel: cancelContext)
    }

    /**
     The provided closure executes when this promise rejects with the specific error passed in. A final `catch` is still required at the end of the chain.

     Rejecting a promise cascades: rejecting all subsequent promises (unless
     recover is invoked) thus you will typically place your catch at the end
     of a chain. Often utility promises will not have a catch, instead
     delegating the error handling to the caller.

     - Parameter only: The specific error to be caught and handled.
     - Parameter on: The queue to which the provided closure dispatches.
     - Parameter execute: The handler to execute if this promise is rejected with the provided error.
     - Note: Since this method handles only specific errors, supplying a `CatchPolicy` is unsupported. You can instead specify e.g. your cancellable error.
     - SeeAlso: [Cancellation](https://github.com/mxcl/PromiseKit/blob/master/Documentation/CommonPatterns.md#cancellation)
     */
    public func `catch`<E: Swift.Error>(only: E, on: Dispatcher = conf.dd, _ body: @escaping(E) -> Void) -> CancellableCascadingFinalizer where E: Equatable {
        return CancellableCascadingFinalizer(pmkCascadingFinalizer.catch(only: only, on: on, body), cancel: cancelContext)
    }

    /**
     The provided closure executes when this promise rejects with an error of the type passed in. A final `catch` is still required at the end of the chain.

     Rejecting a promise cascades: rejecting all subsequent promises (unless
     recover is invoked) thus you will typically place your catch at the end
     of a chain. Often utility promises will not have a catch, instead
     delegating the error handling to the caller.

     - Parameter only: The error type to be caught and handled.
     - Parameter on: The queue to which the provided closure dispatches.
     - Parameter execute: The handler to execute if this promise is rejected with the provided error type.
     - SeeAlso: [Cancellation](https://github.com/mxcl/PromiseKit/blob/master/Documentation/CommonPatterns.md#cancellation)
     */
    public func `catch`<E: Swift.Error>(only: E.Type, on: Dispatcher = conf.dd, policy: CatchPolicy = conf.catchPolicy, _ body: @escaping(E) -> Void) -> CancellableCascadingFinalizer {
        return CancellableCascadingFinalizer(pmkCascadingFinalizer.catch(only: only, on: on, policy: policy, body), cancel: cancelContext)
    }
    
    /// Set a default Dispatcher for the chain. Within the chain, this Dispatcher will remain the
    /// default until you change it, even if you dispatch individual closures to other Dispatchers.
    ///
    /// - Parameters:
    ///   - on: The new default Dispatcher. Use `.default` to return to normal dispatching.
    
    public func dispatch(on: Dispatcher) -> CancellableCascadingFinalizer {
        return CancellableCascadingFinalizer(pmkCascadingFinalizer.dispatch(on: on), cancel: cancelContext)
    }

    /**
     Consumes the Swift unused-result warning.
     - Note: You should `catch`, but in situations where you know you don’t need a `catch`, `cauterize` makes your intentions clear.
     */
    @discardableResult
    public func cauterize() -> CancellableFinalizer {
        return self.catch(policy: .allErrors) {
            conf.logHandler(.cauterized($0))
        }
    }
}

public extension CancellableCatchMixin {
    /**
     The provided closure executes when this cancellable promise rejects.
     
     Unlike `catch`, `recover` continues the chain. It can return a replacement promise or rethrow.
     Use `recover` in circumstances where recovering the chain from certain errors is a possibility. For example:

         let context = firstly {
             CLLocationManager.requestLocation()
         }.recover { error in
             guard error == CLError.unknownLocation else { throw error }
             return .value(CLLocation.chicago)
         }.cancelContext
     
         //…
     
         context.cancel()
     
     - Parameter on: The dispatcher that executes the provided closure.
     - Parameter body: The handler to execute if this promise is rejected.
     - SeeAlso: [Cancellation](https://github.com/mxcl/PromiseKit/blob/master/Documentation/CommonPatterns.md#cancellation)
     */
    func recover<V: CancellableThenable>(on: Dispatcher = conf.dd, policy: CatchPolicy = conf.catchPolicy, _ body: @escaping(Error) throws -> V) -> CancellablePromise<C.T> where V.U.T == C.T {
        let cancelItemList = CancelItemList()

        let cancelBody = { (error: Error) throws -> V.U in
            _ = self.cancelContext.removeItems(self.cancelItemList, clearList: true)
            let rval = try body(error)
            if policy == .allErrors || error.isCancelled {
                self.cancelContext.recover()
            }
            self.cancelContext.append(context: rval.cancelContext, thenableCancelItemList: cancelItemList)
            return rval.thenable
        }
        
        let promise = self.catchable.recover(on: on, policy: policy, cancelBody)
        if thenable.result != nil && policy == .allErrors {
            self.cancelContext.recover()
        }
        return CancellablePromise(promise: promise, context: self.cancelContext, cancelItemList: cancelItemList)
    }
    
    /**
     The provided closure executes when this cancellable promise rejects.
     
     Unlike `catch`, `recover` continues the chain. It can return a replacement promise or rethrow.
     Use `recover` in circumstances where recovering the chain from certain errors is a possibility. For example:

         let context = firstly {
             CLLocationManager.requestLocation()
         }.cancellize().recover { error in
             guard error == CLError.unknownLocation else { throw error }
             return Promise.value(CLLocation.chicago)
         }.cancelContext
     
         //…
     
         context.cancel()
     
     - Parameter on: The dispatcher that executes the provided closure.
     - Parameter policy: The default policy does not execute your handler for cancellation errors.
     - Parameter body: The handler to execute if this promise is rejected.
     - SeeAlso: [Cancellation](https://github.com/mxcl/PromiseKit/blob/master/Documentation/CommonPatterns.md#cancellation)
     */
    func recover<V: Thenable>(on: Dispatcher = conf.dd, policy: CatchPolicy = conf.catchPolicy, _ body: @escaping(Error) throws -> V) -> CancellablePromise<C.T> where V.T == C.T {
        let cancelBody = { (error: Error) throws -> V in
            _ = self.cancelContext.removeItems(self.cancelItemList, clearList: true)
            let rval = try body(error)
            if policy == .allErrors || error.isCancelled {
                self.cancelContext.recover()
            }
            return rval
        }
        
        let promise = self.catchable.recover(on: on, policy: policy, cancelBody)
        if thenable.result != nil && policy == .allErrors {
            self.cancelContext.recover()
        }
        let cancellablePromise = CancellablePromise(promise: promise, context: self.cancelContext)
        if let cancellable = promise.cancellable {
            self.cancelContext.append(cancellable: cancellable, reject: promise.rejectIfCancelled, thenable: cancellablePromise)
        }
        return cancellablePromise
    }

    /**
     The provided closure executes when this cancellable promise rejects with the specific error passed in.

     Unlike `catch`, `recover` continues the chain. It can return a replacement promise or rethrow.
     Use `recover` in circumstances where recovering the chain from certain errors is a possibility. For example:

         firstly {
             CLLocationManager.requestLocation()
         }.recover(CLError.unknownLocation) {
             return .value(CLLocation.chicago)
         }

     - Parameter only: The specific error to be recovered (e.g., `PMKError.emptySequence`)
     - Parameter on: The dispatcher that executes the provided closure.
     - Parameter body: The handler to execute if this promise is rejected with the provided error.
     - Note: Since this method recovers only specific errors, supplying a `CatchPolicy` is unsupported.
     - SeeAlso: [Cancellation](https://github.com/mxcl/PromiseKit/blob/master/Documentation/CommonPatterns.md#cancellation)
     */
    func recover<V: CancellableThenable, E: Swift.Error>(only: E, on: Dispatcher = conf.dd, _ body: @escaping(E) throws -> V) -> CancellablePromise<C.T> where V.U.T == C.T, E: Equatable {
        let cancelItemList = CancelItemList()

        let cancelBody = { (error: E) throws -> V.U in
            _ = self.cancelContext.removeItems(self.cancelItemList, clearList: true)
            let rval = try body(error)
            if error.isCancelled {
                self.cancelContext.recover()
            }
            self.cancelContext.append(context: rval.cancelContext, thenableCancelItemList: cancelItemList)
            return rval.thenable
        }
        
        let promise = self.catchable.recover(only: only, on: on, cancelBody)
        if thenable.result != nil && only.isCancelled {
            self.cancelContext.recover()
        }
        return CancellablePromise(promise: promise, context: self.cancelContext, cancelItemList: cancelItemList)
    }

    /**
     The provided closure executes when this cancellable promise rejects with the specific error passed in.

     Unlike `catch`, `recover` continues the chain. It can return a replacement promise or rethrow.
     Use `recover` in circumstances where recovering the chain from certain errors is a possibility. For example:

         firstly {
             CLLocationManager.requestLocation()
         }.recover(CLError.unknownLocation) {
             return Promise.value(CLLocation.chicago)
         }

     - Parameter only: The specific error to be recovered.
     - Parameter on: The queue to which the provided closure dispatches.
     - Parameter body: The handler to execute if this promise is rejected with the provided error.
     - Note: Since this method recovers only specific errors, supplying a `CatchPolicy` is unsupported. You can instead specify e.g. your cancellable error.
     - SeeAlso: [Cancellation](https://github.com/mxcl/PromiseKit/blob/master/Documentation/CommonPatterns.md#cancellation)
     */
    func recover<V: Thenable, E: Swift.Error>(only: E, on: Dispatcher = conf.dd, _ body: @escaping(E) throws -> V) -> CancellablePromise<C.T> where V.T == C.T, E: Equatable {
        let cancelBody = { (error: E) throws -> V in
            _ = self.cancelContext.removeItems(self.cancelItemList, clearList: true)
            let rval = try body(error)
            if error.isCancelled {
                self.cancelContext.recover()
            }
            return rval
        }
        
        let promise = self.catchable.recover(only: only, on: on, cancelBody)
        let cancellablePromise = CancellablePromise(promise: promise, context: self.cancelContext)
        if let cancellable = promise.cancellable {
            self.cancelContext.append(cancellable: cancellable, reject: promise.rejectIfCancelled, thenable: cancellablePromise)
        }
        return cancellablePromise
    }

    /**
     The provided closure executes when this cancellable promise rejects with an error of the type passed in.

     Unlike `catch`, `recover` continues the chain. It can return a replacement promise or rethrow.
     Use `recover` in circumstances where recovering the chain from certain errors is a possibility. For example:

         firstly {
             API.fetchData()
         }.recover(FetchError.self) { error in
             guard case .missingImage(let partialData) = error else { throw error }
             //…
             return .value(dataWithDefaultImage)
         }

     - Parameter only: The error type to be recovered.
     - Parameter on: The dispatcher that executes the provided closure.
     - Parameter policy: The default policy does not execute your handler for cancellation errors.
     - Parameter body: The handler to execute if this promise is rejected with the provided error type.
     - SeeAlso: [Cancellation](https://github.com/mxcl/PromiseKit/blob/master/Documentation/CommonPatterns.md#cancellation)
     */
    func recover<V: CancellableThenable, E: Swift.Error>(only: E.Type, on: Dispatcher = conf.dd, policy: CatchPolicy = conf.catchPolicy, _ body: @escaping(E) throws -> V) -> CancellablePromise<C.T> where V.U.T == C.T {
        let cancelItemList = CancelItemList()

        let cancelBody = { (error: E) throws -> V.U in
            _ = self.cancelContext.removeItems(self.cancelItemList, clearList: true)
            let rval = try body(error)
            if policy == .allErrors || error.isCancelled {
                self.cancelContext.recover()
            }
            self.cancelContext.append(context: rval.cancelContext, thenableCancelItemList: cancelItemList)
            return rval.thenable
        }
        
        let promise = self.catchable.recover(only: only, on: on, policy: policy, cancelBody)
        if thenable.result != nil && policy == .allErrors {
            self.cancelContext.recover()
        }
        return CancellablePromise(promise: promise, context: self.cancelContext, cancelItemList: cancelItemList)
    }

    /**
     The provided closure executes when this cancellable promise rejects with an error of the type passed in.

     Unlike `catch`, `recover` continues the chain. It can return a replacement promise or rethrow.
     Use `recover` in circumstances where recovering the chain from certain errors is a possibility. For example:

         firstly {
             API.fetchData()
         }.recover(FetchError.self) { error in
             guard case .missingImage(let partialData) = error else { throw error }
             //…
             return Promise.value(dataWithDefaultImage)
         }

     - Parameter only: The error type to be recovered.
     - Parameter on: The queue to which the provided closure dispatches.
     - Parameter body: The handler to execute if this promise is rejected with the provided error type.
     - SeeAlso: [Cancellation](https://github.com/mxcl/PromiseKit/blob/master/Documentation/CommonPatterns.md#cancellation)
     */
    func recover<V: Thenable, E: Swift.Error>(only: E.Type, on: Dispatcher = conf.dd, policy: CatchPolicy = conf.catchPolicy, _ body: @escaping(E) throws -> V) -> CancellablePromise<C.T> where V.T == C.T {
        let cancelBody = { (error: E) throws -> V in
            _ = self.cancelContext.removeItems(self.cancelItemList, clearList: true)
            let rval = try body(error)
            if policy == .allErrors {
                self.cancelContext.recover()
            }
            return rval
        }
        
        let promise = self.catchable.recover(only: only, on: on, policy: policy, cancelBody)
        if thenable.result != nil && policy == .allErrors {
            self.cancelContext.recover()
        }
        let cancellablePromise = CancellablePromise(promise: promise, context: self.cancelContext)
        if let cancellable = promise.cancellable {
            self.cancelContext.append(cancellable: cancellable, reject: promise.rejectIfCancelled, thenable: cancellablePromise)
        }
        return cancellablePromise
    }

    /**
     The provided closure executes when this cancellable promise resolves, whether it rejects or not.
     
         let context = firstly {
             UIApplication.shared.networkActivityIndicatorVisible = true
             //…  returns a cancellable promise
         }.done {
             //…
         }.ensure {
             UIApplication.shared.networkActivityIndicatorVisible = false
         }.catch {
             //…
         }.cancelContext
     
         //…
     
         context.cancel()

     - Parameter on: The dispatcher that executes the provided closure.
     - Parameter body: The closure that executes when this promise resolves.
     - Returns: A new promise, resolved with this promise’s resolution.
     */
    func ensure(on: Dispatcher = conf.dd, _ body: @escaping () -> Void) -> CancellablePromise<C.T> {
        let rp = CancellablePromise<C.T>.pending()
        rp.promise.cancelContext = self.cancelContext
        rp.promise.dispatchState = self.catchable.dispatchState.nextState(givenDispatcher: on)
        self.catchable.pipe { result in
            rp.promise.dispatch {
                body()
                switch result {
                case .success(let value):
                    if let error = self.cancelContext.cancelledError {
                        rp.resolver.reject(error)
                    } else {
                        rp.resolver.fulfill(value)
                    }
                case .failure(let error):
                    rp.resolver.reject(error)
                }
            }
        }
        return rp.promise
    }
    
    /**
     The provided closure executes when this cancellable promise resolves, whether it rejects or not.
     The chain waits on the returned `CancellablePromise<Void>`.

         let context = firstly {
             setup() // returns a cancellable promise
         }.done {
             //…
         }.ensureThen {
             teardown()  // -> CancellablePromise<Void>
         }.catch {
             //…
         }.cancelContext
     
         //…
     
         context.cancel()

     - Parameter on: The dispatcher that executes the provided closure.
     - Parameter body: The closure that executes when this promise resolves.
     - Returns: A new promise, resolved with this promise’s resolution.
     */
    func ensureThen(on: Dispatcher = conf.dd, _ body: @escaping () -> CancellablePromise<Void>) -> CancellablePromise<C.T> {
        let rp = CancellablePromise<C.T>.pending()
        rp.promise.cancelContext = cancelContext
        rp.promise.dispatchState = self.catchable.dispatchState.nextState(givenDispatcher: on)
        self.catchable.pipe { result in
            rp.promise.dispatch {
                let rv = body()
                rp.promise.appendCancelContext(from: rv)
                
                rv.done {
                    switch result {
                    case .success(let value):
                        if let error = self.cancelContext.cancelledError {
                            rp.resolver.reject(error)
                        } else {
                            rp.resolver.fulfill(value)
                        }
                    case .failure(let error):
                        rp.resolver.reject(error)
                    }
                }.catch(policy: .allErrors) {
                    rp.resolver.reject($0)
                }
            }
        }
        return rp.promise
    }
    
    /**
     Consumes the Swift unused-result warning.
     - Note: You should `catch`, but in situations where you know you don’t need a `catch`, `cauterize` makes your intentions clear.
     */
    @discardableResult
    func cauterize() -> CancellableFinalizer {
        return self.catch(policy: .allErrors) {
            conf.logHandler(.cauterized($0))
        }
    }
}

public extension CancellableCatchMixin where C.T == Void {
    /**
     The provided closure executes when this cancellable promise rejects.
     
     This variant of `recover` ensures that no error is thrown from the handler and allows specifying a catch policy.
     
     - Parameter on: The dispatcher that executes the provided closure.
     - Parameter body: The handler to execute if this promise is rejected.
     - SeeAlso: [Cancellation](https://github.com/mxcl/PromiseKit/blob/master/Documentation/CommonPatterns.md#cancellation)
     */
    func recover(on: Dispatcher = conf.dd, policy: CatchPolicy = conf.catchPolicy, _ body: @escaping(Error) throws -> Void) -> CancellablePromise<Void> {
        let cancelBody = { (error: Error) throws -> Void in
            _ = self.cancelContext.removeItems(self.cancelItemList, clearList: true)
            try body(error)
            if policy == .allErrors {
                self.cancelContext.recover()
            }
        }
        
        let promise = self.catchable.recover(on: on, policy: policy, cancelBody)
        if thenable.result != nil && policy == .allErrors {
            self.cancelContext.recover()
        }
        return CancellablePromise(promise: promise, context: self.cancelContext)
    }


    /**
     The provided closure executes when this cancellable promise rejects with the specific error passed in.

     Unlike `catch`, `recover` continues the chain. It can return a replacement promise or rethrow.
     Use `recover` in circumstances where recovering the chain from certain errors is a possibility.

     - Parameter only: The specific error to be recovered.
     - Parameter on: The queue to which the provided closure dispatches.
     - Parameter body: The handler to execute if this promise is rejected with the provided error.
     - Note: Since this method recovers only specific errors, supplying a `CatchPolicy` is unsupported. You can instead specify e.g. your cancellable error.
     - SeeAlso: [Cancellation](https://github.com/mxcl/PromiseKit/blob/master/Documentation/CommonPatterns.md#cancellation)
     */
    func recover<E: Swift.Error>(only: E, on: Dispatcher = conf.dd, _ body: @escaping(E) throws -> Void)
        -> CancellablePromise<Void> where E: Equatable
    {
        let cancelBody = { (error: E) throws -> Void in
            _ = self.cancelContext.removeItems(self.cancelItemList, clearList: true)
            try body(error)
            if error.isCancelled {
                self.cancelContext.recover()
            }
        }
        
        let promise = self.catchable.recover(only: only, on: on, cancelBody)
        if thenable.result != nil && only.isCancelled {
            self.cancelContext.recover()
        }
        return CancellablePromise(promise: promise, context: self.cancelContext)
    }

    /**
     The provided closure executes when this cancellable promise rejects with an error of the type passed in.

     Unlike `catch`, `recover` continues the chain. It can return a replacement promise or rethrow.
     Use `recover` in circumstances where recovering the chain from certain errors is a possibility.

     - Parameter only: The error type to be recovered.
     - Parameter on: The queue to which the provided closure dispatches.
     - Parameter body: The handler to execute if this promise is rejected with the provided error type.
     - SeeAlso: [Cancellation](https://github.com/mxcl/PromiseKit/blob/master/Documentation/CommonPatterns.md#cancellation)
     */
    func recover<E: Swift.Error>(only: E.Type, on: Dispatcher = conf.dd, policy: CatchPolicy = conf.catchPolicy, _ body: @escaping(E) throws -> Void) -> CancellablePromise<Void> {
        let cancelBody = { (error: E) throws -> Void in
            _ = self.cancelContext.removeItems(self.cancelItemList, clearList: true)
            try body(error)
            if policy == .allErrors || error.isCancelled {
                self.cancelContext.recover()
            }
        }
        
        let promise = self.catchable.recover(only: only, on: on, policy: policy, cancelBody)
        if thenable.result != nil && policy == .allErrors {
            self.cancelContext.recover()
        }
        return CancellablePromise(promise: promise, context: self.cancelContext)
    }
}
